Running simulation for years 2011 thru 2011
Simulation root seed: None
Running simulation for year 2011 in new process: started on Wed Feb 12 10:48:10 2014Cache Directory set to: c:/users/janowicz/dropbox/repos/urbansim_drcog\data\drcog2/runs\run_92.run_2014_02_12_10_48
Start simulation run: started on Wed Feb 12 10:48:10 2014
    random seed = (1052667152,)
    Starting simulation for year 2011: started on Wed Feb 12 10:48:10 2014    Starting simulation for year 2011: completed................44 min, 20.1 sec
Start simulation run: completed.................................44 min, 20.1 sec
Running simulation for year 2011 in new process: completed......44 min, 20.5 sec
Done running simulation for years 2011 thru 2011
Cache directory for run 93 set to c:/users/janowicz/dropbox/repos/urbansim_drcog\data\drcog2/runs\run_93.run_2014_02_12_12_06
Running opus_core.store.utils.cache_flt_data.CacheFltData: started on Wed Feb 12 12:06:44 2014
    Caching files from 'C:\Users\janowicz\Dropbox\repos\urbansim_drcog\src\opus_core\data/test_cache/' 
    to 'c:/users/janowicz/dropbox/repos/urbansim_drcog\data\drcog2/runs\run_93.run_2014_02_12_12_06'.
Running opus_core.store.utils.cache_flt_data.CacheFltData: completed.....0.0 sec
Logging to file: c:/users/janowicz/dropbox/repos/urbansim_drcog\data\drcog2/runs\run_93.run_2014_02_12_12_06\run_multiprocess.log
Running simulation for years 2011 thru 2011
Simulation root seed: None
Running simulation for year 2011 in new process: started on Wed Feb 12 12:06:44 2014
    Closing log file: c:/users/janowicz/dropbox/repos/urbansim_drcog\data\drcog2/runs\run_93.run_2014_02_12_12_06\run_multiprocess.log
    Invoking: C:\Anaconda\python.exe C:\Users\janowicz\Dropbox\repos\urbansim_drcog\src\opus_core\model_coordinators\model_system.py -r c:\users\janowicz\appdata\local\temp\tmptwoigy\resources.pickle --log-file-name run_multiprocess.log
Running simulation for year 2011 in new process: completed...............0.8 sec
ERROR: Unexpected Error From Model
Traceback (most recent call last):
  File "C:\Users\janowicz\Dropbox\repos\urbansim_drcog\src\opus_gui\scenarios_manager\run\run_simulation.py", line 269, in run
    scenario_name=self.scenariotorun)
  File "C:\Users\janowicz\Dropbox\repos\urbansim_drcog\src\opus_core\services\run_server\run_manager.py", line 123, in run_run
    model_system.run_multiprocess(run_resources)
  File "C:\Users\janowicz\Dropbox\repos\urbansim_drcog\src\opus_core\model_coordinators\model_system.py", line 479, in run_multiprocess
    log_file=log_file)
  File "C:\Users\janowicz\Dropbox\repos\urbansim_drcog\src\opus_core\model_coordinators\model_system.py", line 512, in _run_each_year_as_separate_process
    resources, optional_args=optional_args)
  File "C:\Users\janowicz\Dropbox\repos\urbansim_drcog\src\opus_core\model_coordinators\model_system.py", line 585, in _fork_new_process
    success = self.forked_processes[-1].fork_new_process(module_name, resources, **key_args)
  File "C:\Users\janowicz\Dropbox\repos\urbansim_drcog\src\opus_core\fork_process.py", line 74, in fork_new_process
    self.wait()
  File "C:\Users\janowicz\Dropbox\repos\urbansim_drcog\src\opus_core\fork_process.py", line 90, in wait
    self.check_status()
  File "C:\Users\janowicz\Dropbox\repos\urbansim_drcog\src\opus_core\fork_process.py", line 101, in check_status
    raise StandardError("Child python process exited with failure.\nCalling module: %s\nSystem command: %s" % (self.module_name, self.python_cmd))
StandardError: Child python process exited with failure.
Calling module: opus_core.model_coordinators.model_system
System command: ['C:\\Anaconda\\python.exe', 'C:\\Users\\janowicz\\Dropbox\\repos\\urbansim_drcog\\src\\opus_core\\model_coordinators\\model_system.py', '-r', 'c:\\users\\janowicz\\appdata\\local\\temp\\tmptwoigy\\resources.pickle', '--log-file-name', 'run_multiprocess.log']

Cache directory for run 94 set to c:/users/janowicz/dropbox/repos/urbansim_drcog\data\drcog2/runs\run_94.run_2014_02_12_12_07
Running opus_core.store.utils.cache_flt_data.CacheFltData: started on Wed Feb 12 12:07:35 2014
    Caching files from 'C:\Users\janowicz\Dropbox\repos\urbansim_drcog\src\opus_core\data/test_cache/' 
    to 'c:/users/janowicz/dropbox/repos/urbansim_drcog\data\drcog2/runs\run_94.run_2014_02_12_12_07'.
Running opus_core.store.utils.cache_flt_data.CacheFltData: completed.....0.0 sec
Logging to file: c:/users/janowicz/dropbox/repos/urbansim_drcog\data\drcog2/runs\run_94.run_2014_02_12_12_07\run_multiprocess.log
Running simulation for years 2011 thru 2011
Simulation root seed: None
Running simulation for year 2011 in new process: started on Wed Feb 12 12:07:35 2014
    Closing log file: c:/users/janowicz/dropbox/repos/urbansim_drcog\data\drcog2/runs\run_94.run_2014_02_12_12_07\run_multiprocess.log
    Invoking: C:\Anaconda\python.exe C:\Users\janowicz\Dropbox\repos\urbansim_drcog\src\opus_core\model_coordinators\model_system.py -r c:\users\janowicz\appdata\local\temp\tmpy74ez1\resources.pickle --log-file-name run_multiprocess.log
Running simulation for year 2011 in new process: completed...............0.8 sec
ERROR: Unexpected Error From Model
Traceback (most recent call last):
  File "C:\Users\janowicz\Dropbox\repos\urbansim_drcog\src\opus_gui\scenarios_manager\run\run_simulation.py", line 269, in run
    scenario_name=self.scenariotorun)
  File "C:\Users\janowicz\Dropbox\repos\urbansim_drcog\src\opus_core\services\run_server\run_manager.py", line 123, in run_run
    model_system.run_multiprocess(run_resources)
  File "C:\Users\janowicz\Dropbox\repos\urbansim_drcog\src\opus_core\model_coordinators\model_system.py", line 479, in run_multiprocess
    log_file=log_file)
  File "C:\Users\janowicz\Dropbox\repos\urbansim_drcog\src\opus_core\model_coordinators\model_system.py", line 512, in _run_each_year_as_separate_process
    resources, optional_args=optional_args)
  File "C:\Users\janowicz\Dropbox\repos\urbansim_drcog\src\opus_core\model_coordinators\model_system.py", line 585, in _fork_new_process
    success = self.forked_processes[-1].fork_new_process(module_name, resources, **key_args)
  File "C:\Users\janowicz\Dropbox\repos\urbansim_drcog\src\opus_core\fork_process.py", line 74, in fork_new_process
    self.wait()
  File "C:\Users\janowicz\Dropbox\repos\urbansim_drcog\src\opus_core\fork_process.py", line 90, in wait
    self.check_status()
  File "C:\Users\janowicz\Dropbox\repos\urbansim_drcog\src\opus_core\fork_process.py", line 101, in check_status
    raise StandardError("Child python process exited with failure.\nCalling module: %s\nSystem command: %s" % (self.module_name, self.python_cmd))
StandardError: Child python process exited with failure.
Calling module: opus_core.model_coordinators.model_system
System command: ['C:\\Anaconda\\python.exe', 'C:\\Users\\janowicz\\Dropbox\\repos\\urbansim_drcog\\src\\opus_core\\model_coordinators\\model_system.py', '-r', 'c:\\users\\janowicz\\appdata\\local\\temp\\tmpy74ez1\\resources.pickle', '--log-file-name', 'run_multiprocess.log']

Cache directory for run 95 set to c:/users/janowicz/dropbox/repos/urbansim_drcog\data\drcog2/runs\run_95.run_2014_02_12_12_08
Running opus_core.store.utils.cache_flt_data.CacheFltData: started on Wed Feb 12 12:08:14 2014
    Caching files from 'C:\Users\janowicz\Dropbox\repos\urbansim_drcog\src\opus_core\data/test_cache/' 
    to 'c:/users/janowicz/dropbox/repos/urbansim_drcog\data\drcog2/runs\run_95.run_2014_02_12_12_08'.
Running opus_core.store.utils.cache_flt_data.CacheFltData: completed.....0.0 sec
Logging to file: c:/users/janowicz/dropbox/repos/urbansim_drcog\data\drcog2/runs\run_95.run_2014_02_12_12_08\run_multiprocess.log
Running simulation for years 2011 thru 2011
Simulation root seed: None
Running simulation for year 2011 in new process: started on Wed Feb 12 12:08:14 2014
    Closing log file: c:/users/janowicz/dropbox/repos/urbansim_drcog\data\drcog2/runs\run_95.run_2014_02_12_12_08\run_multiprocess.log
    Invoking: C:\Anaconda\python.exe C:\Users\janowicz\Dropbox\repos\urbansim_drcog\src\opus_core\model_coordinators\model_system.py -r c:\users\janowicz\appdata\local\temp\tmphjwjh5\resources.pickle --log-file-name run_multiprocess.log
Running simulation for year 2011 in new process: completed.......8 min, 48.0 sec
Done running simulation for years 2011 thru 2011
